<sdf version='1.7'>
  <world name='default'>
    <light name='sun' type='directional'>
      <cast_shadows>1</cast_shadows>
      <pose>0 0 10 0 -0 0</pose>
      <diffuse>0.8 0.8 0.8 1</diffuse>
      <specular>0.2 0.2 0.2 1</specular>
      <attenuation>
        <range>1000</range>
        <constant>0.9</constant>
        <linear>0.01</linear>
        <quadratic>0.001</quadratic>
      </attenuation>
      <direction>-0.5 0.1 -0.9</direction>
      <spot>
        <inner_angle>0</inner_angle>
        <outer_angle>0</outer_angle>
        <falloff>0</falloff>
      </spot>
    </light>
    <model name='ground_plane'>
      <static>1</static>
      <link name='link'>
        <collision name='collision'>
          <geometry>
            <plane>
              <normal>0 0 1</normal>
              <size>100 100</size>
            </plane>
          </geometry>
          <surface>
            <contact>
              <collide_bitmask>65535</collide_bitmask>
              <ode/>
            </contact>
            <friction>
              <ode>
                <mu>100</mu>
                <mu2>50</mu2>
              </ode>
              <torsional>
                <ode/>
              </torsional>
            </friction>
            <bounce/>
          </surface>
          <max_contacts>10</max_contacts>
        </collision>
        <visual name='visual'>
          <cast_shadows>0</cast_shadows>
          <geometry>
            <plane>
              <normal>0 0 1</normal>
              <size>100 100</size>
            </plane>
          </geometry>
          <material>
            <script>
              <uri>file://media/materials/scripts/gazebo.material</uri>
              <name>Gazebo/Grey</name>
            </script>
          </material>
        </visual>
        <self_collide>0</self_collide>
        <enable_wind>0</enable_wind>
        <kinematic>0</kinematic>
      </link>
    </model>
    <gravity>0 0 -9.8</gravity>
    <magnetic_field>6e-06 2.3e-05 -4.2e-05</magnetic_field>
    <atmosphere type='adiabatic'/>
    <physics type='ode'>
      <max_step_size>0.001</max_step_size>
      <real_time_factor>1</real_time_factor>
      <real_time_update_rate>1000</real_time_update_rate>
    </physics>
    <scene>
      <ambient>0.4 0.4 0.4 1</ambient>
      <background>0.7 0.7 0.7 1</background>
      <shadows>1</shadows>
    </scene>
    <wind/>
    <spherical_coordinates>
      <surface_model>EARTH_WGS84</surface_model>
      <latitude_deg>0</latitude_deg>
      <longitude_deg>0</longitude_deg>
      <elevation>0</elevation>
      <heading_deg>0</heading_deg>
    </spherical_coordinates>
    <model name='ADHIC_MK1'>
      <link name='base_footprint'>
        <inertial>
          <pose>-1e-06 -0 0.131088 0 -0 0</pose>
          <mass>6.34252</mass>
          <inertia>
            <ixx>0.0698608</ixx>
            <ixy>-1.00001e-06</ixy>
            <ixz>-9.27583e-07</ixz>
            <iyy>0.0698562</iyy>
            <iyz>-3.57858e-07</iyz>
            <izz>0.0322124</izz>
          </inertia>
        </inertial>
        <collision name='base_footprint_fixed_joint_lump__hbot_base_collision'>
          <pose>0 0 0 0 -0 0</pose>
          <geometry>
            <mesh>
              <scale>0.002 0.002 0.002</scale>
              <uri>/home/vedh/catkin_ws/src/eYRC-2022_HolA_Bot/ADHIC_MK1_description/meshes/base_link.stl</uri>
            </mesh>
          </geometry>
          <max_contacts>10</max_contacts>
          <surface>
            <contact>
              <ode/>
            </contact>
            <bounce/>
            <friction>
              <torsional>
                <ode/>
              </torsional>
              <ode/>
            </friction>
          </surface>
        </collision>
        <collision name='base_footprint_fixed_joint_lump__lidar_1_collision_1'>
          <pose>0 0 0.005 0 -0 0</pose>
          <geometry>
            <mesh>
              <scale>0.002 0.002 0.002</scale>
              <uri>/home/vedh/catkin_ws/src/eYRC-2022_HolA_Bot/ADHIC_MK1_description/meshes/lidar_1.stl</uri>
            </mesh>
          </geometry>
          <surface>
            <contact>
              <ode/>
            </contact>
            <friction>
              <ode>
                <mu>0.2</mu>
                <mu2>0.2</mu2>
              </ode>
              <torsional>
                <ode/>
              </torsional>
            </friction>
            <bounce/>
          </surface>
          <max_contacts>10</max_contacts>
        </collision>
        <collision name='base_footprint_fixed_joint_lump__base_camera_link_collision_2'>
          <pose>0.219601 6.2e-05 0.203973 -0.003185 -0.2 0.003185</pose>
          <geometry>
            <box>
              <size>0.001 0.001 0.001</size>
            </box>
          </geometry>
          <surface>
            <contact>
              <ode/>
            </contact>
            <friction>
              <ode/>
              <torsional>
                <ode/>
              </torsional>
            </friction>
            <bounce/>
          </surface>
          <max_contacts>10</max_contacts>
        </collision>
        <collision name='base_footprint_fixed_joint_lump__base_link_collision_3'>
          <pose>0 0 0.2 0 -0 0</pose>
          <geometry>
            <cylinder>
              <length>0.024</length>
              <radius>0.0735</radius>
            </cylinder>
          </geometry>
          <surface>
            <contact>
              <ode/>
            </contact>
            <friction>
              <ode>
                <mu>0.2</mu>
                <mu2>0.2</mu2>
              </ode>
              <torsional>
                <ode/>
              </torsional>
            </friction>
            <bounce/>
          </surface>
          <max_contacts>10</max_contacts>
        </collision>
        <visual name='base_footprint_fixed_joint_lump__hbot_base_visual'>
          <pose>0 0 0 0 -0 0</pose>
          <geometry>
            <mesh>
              <scale>0.002 0.002 0.002</scale>
              <uri>/home/vedh/catkin_ws/src/eYRC-2022_HolA_Bot/ADHIC_MK1_description/meshes/base_link.stl</uri>
            </mesh>
          </geometry>
        </visual>
        <visual name='base_footprint_fixed_joint_lump__lidar_1_visual_1'>
          <pose>0 0 0.05 0 -0 0</pose>
          <geometry>
            <mesh>
              <scale>0.002 0.002 0.002</scale>
              <uri>/home/vedh/catkin_ws/src/eYRC-2022_HolA_Bot/ADHIC_MK1_description/meshes/lidar_1.stl</uri>
            </mesh>
          </geometry>
          <material>
            <script>
              <name>Gazebo/Silver</name>
              <uri>file://media/materials/scripts/gazebo.material</uri>
            </script>
          </material>
        </visual>
        <visual name='base_footprint_fixed_joint_lump__base_camera_link_visual_2'>
          <pose>0.2 0 0.2 1.3707 0.003103 1.57325</pose>
          <geometry>
            <mesh>
              <scale>1 1 1</scale>
              <uri>/home/vedh/catkin_ws/src/eyrc-2022_krishibot/meshes/NAVRS.STL</uri>
            </mesh>
          </geometry>
        </visual>
        <visual name='base_footprint_fixed_joint_lump__base_link_visual_3'>
          <pose>0 0 0.2 0 -0 0</pose>
          <geometry>
            <mesh>
              <scale>1 1 1</scale>
              <uri>/home/vedh/catkin_ws/src/ur_description/meshes/ur5/visual/base.dae</uri>
            </mesh>
          </geometry>
          <material>
            <script>
              <name>Gazebo/Silver</name>
              <uri>file://media/materials/scripts/gazebo.material</uri>
            </script>
          </material>
        </visual>
        <sensor name='head_hokuyo_sensor' type='ray'>
          <visualize>1</visualize>
          <update_rate>40</update_rate>
          <ray>
            <scan>
              <horizontal>
                <samples>720</samples>
                <resolution>1</resolution>
                <min_angle>-1.5708</min_angle>
                <max_angle>1.5708</max_angle>
              </horizontal>
              <vertical>
                <samples>1</samples>
                <min_angle>0</min_angle>
                <max_angle>0</max_angle>
              </vertical>
            </scan>
            <range>
              <min>0.1</min>
              <max>2</max>
              <resolution>0.01</resolution>
            </range>
            <noise>
              <type>gaussian</type>
              <mean>0</mean>
              <stddev>0.01</stddev>
            </noise>
          </ray>
          <plugin name='gazebo_ros_head_hokuyo_controller' filename='libgazebo_ros_laser.so'>
            <topicName>/bot/scan</topicName>
            <frameName>lidar_1</frameName>
            <robotNamespace>/</robotNamespace>
          </plugin>
          <pose>0 0 0.05 0 -0 0</pose>
        </sensor>
        <sensor name='intelrealsense1' type='depth'>
          <always_on>1</always_on>
          <visualize>1</visualize>
          <camera>
            <horizontal_fov>1.047</horizontal_fov>
            <image>
              <width>640</width>
              <height>480</height>
              <format>R8G8B8</format>
            </image>
            <depth_camera>
              <output>depths</output>
            </depth_camera>
            <clip>
              <near>0.1</near>
              <far>100</far>
            </clip>
          </camera>
          <plugin name='intelrealsense1' filename='libgazebo_ros_openni_kinect.so'>
            <alwaysOn>1</alwaysOn>
            <updateRate>10.0</updateRate>
            <cameraName>base_camera</cameraName>
            <frameName>base_camera_depth_frame</frameName>
            <imageTopicName>/camera1/color/image_raw1</imageTopicName>
            <depthImageTopicName>/camera1/depth/image_raw1</depthImageTopicName>
            <pointCloudTopicName>depth1/points1</pointCloudTopicName>
            <cameraInfoTopicName>/camera1/color/camera_info1</cameraInfoTopicName>
            <depthImageCameraInfoTopicName>/camera1/depth/camera_info1</depthImageCameraInfoTopicName>
            <pointCloudCutoff>0.2</pointCloudCutoff>
            <pointCloudCutoffMax>10.0</pointCloudCutoffMax>
            <hackBaseline>0.07</hackBaseline>
            <distortionK1>0.0</distortionK1>
            <distortionK2>0.0</distortionK2>
            <distortionK3>0.0</distortionK3>
            <distortionT1>0.0</distortionT1>
            <distortionT2>0.0</distortionT2>
            <CxPrime>0.0</CxPrime>
            <Cx>0.0</Cx>
            <Cy>0.0</Cy>
            <focalLength>0.0</focalLength>
            <robotNamespace>/</robotNamespace>
          </plugin>
          <pose>0.2 0 0.2 -0.003185 -0.2 0.003185</pose>
        </sensor>
        <self_collide>1</self_collide>
        <gravity>1</gravity>
        <enable_wind>0</enable_wind>
        <kinematic>0</kinematic>
      </link>
      <joint name='Rev1' type='revolute'>
        <pose relative_to='base_footprint'>0.084977 -9.5e-05 0.0025 0 -0 0</pose>
        <parent>base_footprint</parent>
        <child>front_wheel_1</child>
        <axis>
          <xyz>1 0.000132 0</xyz>
          <limit>
            <lower>-1e+16</lower>
            <upper>1e+16</upper>
          </limit>
          <dynamics>
            <spring_reference>0</spring_reference>
            <spring_stiffness>0</spring_stiffness>
          </dynamics>
        </axis>
      </joint>
      <link name='front_wheel_1'>
        <pose relative_to='Rev1'>0 0 0 0 -0 0</pose>
        <inertial>
          <pose>0.01 1e-06 0 0 -0 0</pose>
          <mass>0.353255</mass>
          <inertia>
            <ixx>0.000534</ixx>
            <ixy>0</ixy>
            <ixz>0</ixz>
            <iyy>0.000314</iyy>
            <iyz>0</iyz>
            <izz>0.000314</izz>
          </inertia>
        </inertial>
        <collision name='front_wheel_1_collision'>
          <pose>-0.084977 9.5e-05 -0.0025 0 -0 0</pose>
          <geometry>
            <mesh>
              <scale>0.002 0.002 0.002</scale>
              <uri>/home/vedh/catkin_ws/src/eYRC-2022_HolA_Bot/ADHIC_MK1_description/meshes/front_wheel_1.stl</uri>
            </mesh>
          </geometry>
          <surface>
            <contact>
              <ode/>
            </contact>
            <friction>
              <ode>
                <mu>0.2</mu>
                <mu2>0.2</mu2>
              </ode>
              <torsional>
                <ode/>
              </torsional>
            </friction>
            <bounce/>
          </surface>
          <max_contacts>10</max_contacts>
        </collision>
        <visual name='front_wheel_1_visual'>
          <pose>-0.084977 9.5e-05 -0.0025 0 -0 0</pose>
          <geometry>
            <mesh>
              <scale>0.002 0.002 0.002</scale>
              <uri>/home/vedh/catkin_ws/src/eYRC-2022_HolA_Bot/ADHIC_MK1_description/meshes/front_wheel_1.stl</uri>
            </mesh>
          </geometry>
          <material>
            <script>
              <name>Gazebo/Silver</name>
              <uri>file://media/materials/scripts/gazebo.material</uri>
            </script>
          </material>
        </visual>
        <self_collide>1</self_collide>
        <enable_wind>0</enable_wind>
        <kinematic>0</kinematic>
      </link>
      <joint name='Rev2' type='revolute'>
        <pose relative_to='base_footprint'>-0.042626 -0.073569 0.0025 0 -0 0</pose>
        <parent>base_footprint</parent>
        <child>right_wheel_1</child>
        <axis>
          <xyz>-0.499827 -0.866126 0</xyz>
          <limit>
            <lower>-1e+16</lower>
            <upper>1e+16</upper>
          </limit>
          <dynamics>
            <spring_reference>0</spring_reference>
            <spring_stiffness>0</spring_stiffness>
          </dynamics>
        </axis>
      </joint>
      <link name='right_wheel_1'>
        <pose relative_to='Rev2'>0 0 0 0 -0 0</pose>
        <inertial>
          <pose>-0.004998 -0.008662 0 0 -0 0</pose>
          <mass>0.353255</mass>
          <inertia>
            <ixx>0.000369</ixx>
            <ixy>9.5e-05</ixy>
            <ixz>0</ixz>
            <iyy>0.000479</iyy>
            <iyz>0</iyz>
            <izz>0.000314</izz>
          </inertia>
        </inertial>
        <collision name='right_wheel_1_collision'>
          <pose>0.042626 0.073569 -0.0025 0 -0 0</pose>
          <geometry>
            <mesh>
              <scale>0.002 0.002 0.002</scale>
              <uri>/home/vedh/catkin_ws/src/eYRC-2022_HolA_Bot/ADHIC_MK1_description/meshes/right_wheel_1.stl</uri>
            </mesh>
          </geometry>
          <surface>
            <contact>
              <ode/>
            </contact>
            <friction>
              <ode>
                <mu>0.2</mu>
                <mu2>0.2</mu2>
              </ode>
              <torsional>
                <ode/>
              </torsional>
            </friction>
            <bounce/>
          </surface>
          <max_contacts>10</max_contacts>
        </collision>
        <visual name='right_wheel_1_visual'>
          <pose>0.042626 0.073569 -0.0025 0 -0 0</pose>
          <geometry>
            <mesh>
              <scale>0.002 0.002 0.002</scale>
              <uri>/home/vedh/catkin_ws/src/eYRC-2022_HolA_Bot/ADHIC_MK1_description/meshes/right_wheel_1.stl</uri>
            </mesh>
          </geometry>
          <material>
            <script>
              <name>Gazebo/Silver</name>
              <uri>file://media/materials/scripts/gazebo.material</uri>
            </script>
          </material>
        </visual>
        <self_collide>1</self_collide>
        <enable_wind>0</enable_wind>
        <kinematic>0</kinematic>
      </link>
      <joint name='Rev3' type='revolute'>
        <pose relative_to='base_footprint'>-0.0425 0.073612 0.0025 0 -0 0</pose>
        <parent>base_footprint</parent>
        <child>left_wheel_1</child>
        <axis>
          <xyz>-0.5 0.866025 0</xyz>
          <limit>
            <lower>-1e+16</lower>
            <upper>1e+16</upper>
          </limit>
          <dynamics>
            <spring_reference>0</spring_reference>
            <spring_stiffness>0</spring_stiffness>
          </dynamics>
        </axis>
      </joint>
      <link name='left_wheel_1'>
        <pose relative_to='Rev3'>0 0 0 0 -0 0</pose>
        <inertial>
          <pose>-0.005 0.00866 -0 0 -0 0</pose>
          <mass>0.353255</mass>
          <inertia>
            <ixx>0.000369</ixx>
            <ixy>-9.5e-05</ixy>
            <ixz>0</ixz>
            <iyy>0.000479</iyy>
            <iyz>0</iyz>
            <izz>0.000314</izz>
          </inertia>
        </inertial>
        <collision name='left_wheel_1_collision'>
          <pose>0.0425 -0.073612 -0.0025 0 -0 0</pose>
          <geometry>
            <mesh>
              <scale>0.002 0.002 0.002</scale>
              <uri>/home/vedh/catkin_ws/src/eYRC-2022_HolA_Bot/ADHIC_MK1_description/meshes/left_wheel_1.stl</uri>
            </mesh>
          </geometry>
          <surface>
            <contact>
              <ode/>
            </contact>
            <friction>
              <ode>
                <mu>0.2</mu>
                <mu2>0.2</mu2>
              </ode>
              <torsional>
                <ode/>
              </torsional>
            </friction>
            <bounce/>
          </surface>
          <max_contacts>10</max_contacts>
        </collision>
        <visual name='left_wheel_1_visual'>
          <pose>0.0425 -0.073612 -0.0025 0 -0 0</pose>
          <geometry>
            <mesh>
              <scale>0.002 0.002 0.002</scale>
              <uri>/home/vedh/catkin_ws/src/eYRC-2022_HolA_Bot/ADHIC_MK1_description/meshes/left_wheel_1.stl</uri>
            </mesh>
          </geometry>
          <material>
            <script>
              <name>Gazebo/Silver</name>
              <uri>file://media/materials/scripts/gazebo.material</uri>
            </script>
          </material>
        </visual>
        <self_collide>1</self_collide>
        <enable_wind>0</enable_wind>
        <kinematic>0</kinematic>
      </link>
      <joint name='shoulder_pan_joint' type='revolute'>
        <pose relative_to='base_footprint'>0 0 0.289159 0 -0 0</pose>
        <parent>base_footprint</parent>
        <child>shoulder_link</child>
        <axis>
          <xyz>0 0 1</xyz>
          <limit>
            <lower>-6.28319</lower>
            <upper>6.28319</upper>
            <effort>150</effort>
            <velocity>3.15</velocity>
          </limit>
          <dynamics>
            <damping>0</damping>
            <friction>0</friction>
            <spring_reference>0</spring_reference>
            <spring_stiffness>0</spring_stiffness>
          </dynamics>
        </axis>
      </joint>
      <link name='shoulder_link'>
        <pose relative_to='shoulder_pan_joint'>0 0 0 0 -0 0</pose>
        <inertial>
          <pose>0 0 0 0 -0 0</pose>
          <mass>3.7</mass>
          <inertia>
            <ixx>0.0102675</ixx>
            <ixy>0</ixy>
            <ixz>0</ixz>
            <iyy>0.0102675</iyy>
            <iyz>0</iyz>
            <izz>0.00666</izz>
          </inertia>
        </inertial>
        <collision name='shoulder_link_collision'>
          <pose>0 0 0 0 -0 0</pose>
          <geometry>
            <cylinder>
              <length>0.134</length>
              <radius>0.0595</radius>
            </cylinder>
          </geometry>
          <surface>
            <contact>
              <ode/>
            </contact>
            <friction>
              <ode/>
              <torsional>
                <ode/>
              </torsional>
            </friction>
            <bounce/>
          </surface>
          <max_contacts>10</max_contacts>
        </collision>
        <visual name='shoulder_link_visual'>
          <pose>0 0 0 0 -0 0</pose>
          <geometry>
            <mesh>
              <scale>1 1 1</scale>
              <uri>/home/vedh/catkin_ws/src/ur_description/meshes/ur5/visual/shoulder.dae</uri>
            </mesh>
          </geometry>
        </visual>
        <self_collide>1</self_collide>
        <enable_wind>0</enable_wind>
        <kinematic>0</kinematic>
      </link>
      <joint name='shoulder_lift_joint' type='revolute'>
        <pose relative_to='shoulder_link'>0 0.13585 0 0 -0.785398 0</pose>
        <parent>shoulder_link</parent>
        <child>upper_arm_link</child>
        <axis>
          <xyz>0 1 0</xyz>
          <limit>
            <lower>-6.28319</lower>
            <upper>6.28319</upper>
            <effort>150</effort>
            <velocity>3.15</velocity>
          </limit>
          <dynamics>
            <damping>0</damping>
            <friction>0</friction>
            <spring_reference>0</spring_reference>
            <spring_stiffness>0</spring_stiffness>
          </dynamics>
        </axis>
      </joint>
      <link name='upper_arm_link'>
        <pose relative_to='shoulder_lift_joint'>0 0 0 0 -0 0</pose>
        <inertial>
          <pose>0 0 0.28 0 -0 0</pose>
          <mass>8.393</mass>
          <inertia>
            <ixx>0.226891</ixx>
            <ixy>0</ixy>
            <ixz>0</ixz>
            <iyy>0.226891</iyy>
            <iyz>0</iyz>
            <izz>0.0151074</izz>
          </inertia>
        </inertial>
        <collision name='upper_arm_link_collision'>
          <pose>0 0 0.22 0 -0 0</pose>
          <geometry>
            <cylinder>
              <length>0.545</length>
              <radius>0.045</radius>
            </cylinder>
          </geometry>
          <surface>
            <contact>
              <ode/>
            </contact>
            <friction>
              <ode/>
              <torsional>
                <ode/>
              </torsional>
            </friction>
            <bounce/>
          </surface>
          <max_contacts>10</max_contacts>
        </collision>
        <visual name='upper_arm_link_visual'>
          <pose>0 0 0 0 -0 0</pose>
          <geometry>
            <mesh>
              <scale>1 1 1</scale>
              <uri>/home/vedh/catkin_ws/src/ur_description/meshes/ur5/visual/upperarm.dae</uri>
            </mesh>
          </geometry>
        </visual>
        <self_collide>1</self_collide>
        <enable_wind>0</enable_wind>
        <kinematic>0</kinematic>
      </link>
      <joint name='elbow_joint' type='revolute'>
        <pose relative_to='upper_arm_link'>0 -0.1197 0.425 3.14159 0.785398 3.14159</pose>
        <parent>upper_arm_link</parent>
        <child>forearm_link</child>
        <axis>
          <xyz>0 1 0</xyz>
          <limit>
            <lower>-3.14159</lower>
            <upper>3.14159</upper>
            <effort>150</effort>
            <velocity>3.15</velocity>
          </limit>
          <dynamics>
            <damping>0</damping>
            <friction>0</friction>
            <spring_reference>0</spring_reference>
            <spring_stiffness>0</spring_stiffness>
          </dynamics>
        </axis>
      </joint>
      <link name='forearm_link'>
        <pose relative_to='elbow_joint'>0 0 0 0 -0 0</pose>
        <inertial>
          <pose>0 0 0.196125 0 -0 0</pose>
          <mass>2.275</mass>
          <inertia>
            <ixx>0.0312168</ixx>
            <ixy>0</ixy>
            <ixz>0</ixz>
            <iyy>0.0312168</iyy>
            <iyz>0</iyz>
            <izz>0.004095</izz>
          </inertia>
        </inertial>
        <collision name='forearm_link_collision'>
          <pose>0 0 0.18 0 -0 0</pose>
          <geometry>
            <cylinder>
              <length>0.489</length>
              <radius>0.038</radius>
            </cylinder>
          </geometry>
          <surface>
            <contact>
              <ode/>
            </contact>
            <friction>
              <ode/>
              <torsional>
                <ode/>
              </torsional>
            </friction>
            <bounce/>
          </surface>
          <max_contacts>10</max_contacts>
        </collision>
        <visual name='forearm_link_visual'>
          <pose>0 0 0 0 -0 0</pose>
          <geometry>
            <mesh>
              <scale>1 1 1</scale>
              <uri>/home/vedh/catkin_ws/src/ur_description/meshes/ur5/visual/forearm.dae</uri>
            </mesh>
          </geometry>
        </visual>
        <self_collide>1</self_collide>
        <enable_wind>0</enable_wind>
        <kinematic>0</kinematic>
      </link>
      <joint name='wrist_1_joint' type='revolute'>
        <pose relative_to='forearm_link'>0 0 0.39225 3.14159 1.57079 3.14159</pose>
        <parent>forearm_link</parent>
        <child>wrist_1_link</child>
        <axis>
          <xyz>0 1 0</xyz>
          <limit>
            <lower>-6.28319</lower>
            <upper>6.28319</upper>
            <effort>28</effort>
            <velocity>3.2</velocity>
          </limit>
          <dynamics>
            <damping>0</damping>
            <friction>0</friction>
            <spring_reference>0</spring_reference>
            <spring_stiffness>0</spring_stiffness>
          </dynamics>
        </axis>
      </joint>
      <link name='wrist_1_link'>
        <pose relative_to='wrist_1_joint'>0 0 0 0 -0 0</pose>
        <inertial>
          <pose>0 0.093 0 0 -0 0</pose>
          <mass>1.219</mass>
          <inertia>
            <ixx>0.0025599</ixx>
            <ixy>0</ixy>
            <ixz>0</ixz>
            <iyy>0.0025599</iyy>
            <iyz>0</iyz>
            <izz>0.0021942</izz>
          </inertia>
        </inertial>
        <collision name='wrist_1_link_collision'>
          <pose>0 0.093 0.008 0 -0 0</pose>
          <geometry>
            <cylinder>
              <length>0.1</length>
              <radius>0.032</radius>
            </cylinder>
          </geometry>
          <surface>
            <contact>
              <ode/>
            </contact>
            <friction>
              <ode/>
              <torsional>
                <ode/>
              </torsional>
            </friction>
            <bounce/>
          </surface>
          <max_contacts>10</max_contacts>
        </collision>
        <visual name='wrist_1_link_visual'>
          <pose>0 0 0 0 -0 0</pose>
          <geometry>
            <mesh>
              <scale>1 1 1</scale>
              <uri>/home/vedh/catkin_ws/src/ur_description/meshes/ur5/visual/wrist1.dae</uri>
            </mesh>
          </geometry>
        </visual>
        <self_collide>1</self_collide>
        <enable_wind>0</enable_wind>
        <kinematic>0</kinematic>
      </link>
      <joint name='wrist_2_joint' type='revolute'>
        <pose relative_to='wrist_1_link'>0 0.093 0 0 -0 1.5708</pose>
        <parent>wrist_1_link</parent>
        <child>wrist_2_link</child>
        <axis>
          <xyz>0 0 1</xyz>
          <limit>
            <lower>-6.28319</lower>
            <upper>6.28319</upper>
            <effort>28</effort>
            <velocity>3.2</velocity>
          </limit>
          <dynamics>
            <damping>0</damping>
            <friction>0</friction>
            <spring_reference>0</spring_reference>
            <spring_stiffness>0</spring_stiffness>
          </dynamics>
        </axis>
      </joint>
      <link name='wrist_2_link'>
        <pose relative_to='wrist_2_joint'>0 0 0 0 -0 0</pose>
        <inertial>
          <pose>0 0 0.09465 0 -0 0</pose>
          <mass>1.219</mass>
          <inertia>
            <ixx>0.0025599</ixx>
            <ixy>0</ixy>
            <ixz>0</ixz>
            <iyy>0.0025599</iyy>
            <iyz>0</iyz>
            <izz>0.0021942</izz>
          </inertia>
        </inertial>
        <collision name='wrist_2_link_collision'>
          <pose>0 0 0.09465 1.57 -0 0</pose>
          <geometry>
            <cylinder>
              <length>0.105</length>
              <radius>0.032</radius>
            </cylinder>
          </geometry>
          <surface>
            <contact>
              <ode/>
            </contact>
            <friction>
              <ode/>
              <torsional>
                <ode/>
              </torsional>
            </friction>
            <bounce/>
          </surface>
          <max_contacts>10</max_contacts>
        </collision>
        <visual name='wrist_2_link_visual'>
          <pose>0 0 0 0 -0 0</pose>
          <geometry>
            <mesh>
              <scale>1 1 1</scale>
              <uri>/home/vedh/catkin_ws/src/ur_description/meshes/ur5/visual/wrist2.dae</uri>
            </mesh>
          </geometry>
        </visual>
        <self_collide>1</self_collide>
        <enable_wind>0</enable_wind>
        <kinematic>0</kinematic>
      </link>
      <joint name='wrist_3_joint' type='revolute'>
        <pose relative_to='wrist_2_link'>0 0 0.09465 0 -0 0</pose>
        <parent>wrist_2_link</parent>
        <child>wrist_3_link</child>
        <axis>
          <xyz>0 1 0</xyz>
          <limit>
            <lower>-6.28319</lower>
            <upper>6.28319</upper>
            <effort>28</effort>
            <velocity>3.2</velocity>
          </limit>
          <dynamics>
            <damping>0</damping>
            <friction>0</friction>
            <spring_reference>0</spring_reference>
            <spring_stiffness>0</spring_stiffness>
          </dynamics>
        </axis>
      </joint>
      <link name='wrist_3_link'>
        <pose relative_to='wrist_3_joint'>0 0 0 0 -0 0</pose>
        <inertial>
          <pose>0 0.076597 -1e-06 1.5708 -0 0</pose>
          <mass>0.824861</mass>
          <inertia>
            <ixx>0.00122749</ixx>
            <ixy>-5.85795e-35</ixy>
            <ixz>2.06792e-19</ixz>
            <iyy>0.00128843</iyy>
            <iyz>-1.38723e-07</iyz>
            <izz>0.000512181</izz>
          </inertia>
        </inertial>
        <collision name='wrist_3_link_collision'>
          <pose>0 0.067 0 1.57 -0 0</pose>
          <geometry>
            <cylinder>
              <length>0.0245</length>
              <radius>0.032</radius>
            </cylinder>
          </geometry>
          <surface>
            <contact>
              <ode/>
            </contact>
            <friction>
              <ode/>
              <torsional>
                <ode/>
              </torsional>
            </friction>
            <bounce/>
          </surface>
          <max_contacts>10</max_contacts>
        </collision>
        <collision name='wrist_3_link_fixed_joint_lump__ee_link_collision_1'>
          <pose>-0 0.0723 0 0 -0 1.5708</pose>
          <geometry>
            <box>
              <size>0.01 0.01 0.01</size>
            </box>
          </geometry>
          <surface>
            <contact>
              <ode/>
            </contact>
            <friction>
              <ode/>
              <torsional>
                <ode/>
              </torsional>
            </friction>
            <bounce/>
          </surface>
          <max_contacts>10</max_contacts>
        </collision>
        <collision name='wrist_3_link_fixed_joint_lump__gripper_base_link_collision_2'>
          <pose>0 0.097 0 1.57079 1.57079 3.14159</pose>
          <geometry>
            <cylinder>
              <length>0.03</length>
              <radius>0.0375</radius>
            </cylinder>
          </geometry>
          <surface>
            <contact>
              <ode>
                <kp>1e+08</kp>
                <kd>1</kd>
              </ode>
            </contact>
            <friction>
              <ode>
                <mu>100000</mu>
                <mu2>100000</mu2>
              </ode>
              <torsional>
                <ode/>
              </torsional>
            </friction>
            <bounce/>
          </surface>
          <max_contacts>10</max_contacts>
        </collision>
        <collision name='wrist_3_link_fixed_joint_lump__camera_link2_collision_3'>
          <pose>1.6e-05 0.27 -0.08 3.14 0 1.57</pose>
          <geometry>
            <box>
              <size>0.001 0.001 0.001</size>
            </box>
          </geometry>
          <surface>
            <contact>
              <ode/>
            </contact>
            <friction>
              <ode/>
              <torsional>
                <ode/>
              </torsional>
            </friction>
            <bounce/>
          </surface>
          <max_contacts>10</max_contacts>
        </collision>
        <visual name='wrist_3_link_visual'>
          <pose>0 0 0 0 -0 0</pose>
          <geometry>
            <mesh>
              <scale>1 1 1</scale>
              <uri>/home/vedh/catkin_ws/src/ur_description/meshes/ur5/visual/wrist3.dae</uri>
            </mesh>
          </geometry>
        </visual>
        <visual name='wrist_3_link_fixed_joint_lump__gripper_base_link_visual_1'>
          <pose>0 0.08 0 0 -0 1.5708</pose>
          <geometry>
            <mesh>
              <scale>1 1 1</scale>
              <uri>/home/vedh/catkin_ws/src/robotiq_85_gripper-master/robotiq_85_description/meshes/visual/robotiq_85_base_link.dae</uri>
            </mesh>
          </geometry>
        </visual>
        <visual name='wrist_3_link_fixed_joint_lump__camera_link2_visual_2'>
          <pose>0 0.25 -0.08 -1.57089 -0.001593 -0.0007</pose>
          <geometry>
            <mesh>
              <scale>1 1 1</scale>
              <uri>/home/vedh/catkin_ws/src/eyrc-2022_krishibot/meshes/NAVRS.STL</uri>
            </mesh>
          </geometry>
        </visual>
        <self_collide>1</self_collide>
        <sensor name='intelrealsense2' type='depth'>
          <always_on>1</always_on>
          <visualize>1</visualize>
          <camera>
            <horizontal_fov>1.047</horizontal_fov>
            <image>
              <width>640</width>
              <height>480</height>
              <format>R8G8B8</format>
            </image>
            <depth_camera>
              <output>depths</output>
            </depth_camera>
            <clip>
              <near>0.1</near>
              <far>100</far>
            </clip>
          </camera>
          <plugin name='intelrealsense' filename='libgazebo_ros_openni_kinect.so'>
            <alwaysOn>1</alwaysOn>
            <updateRate>10.0</updateRate>
            <cameraName>camera2</cameraName>
            <frameName>camera_depth_frame2</frameName>
            <imageTopicName>/camera/color/image_raw2</imageTopicName>
            <depthImageTopicName>/camera/depth/image_raw2</depthImageTopicName>
            <pointCloudTopicName>depth/points2</pointCloudTopicName>
            <cameraInfoTopicName>/camera/color/camera_info2</cameraInfoTopicName>
            <depthImageCameraInfoTopicName>/camera/depth/camera_info2</depthImageCameraInfoTopicName>
            <pointCloudCutoff>0.2</pointCloudCutoff>
            <pointCloudCutoffMax>10.0</pointCloudCutoffMax>
            <hackBaseline>0.07</hackBaseline>
            <distortionK1>0.0</distortionK1>
            <distortionK2>0.0</distortionK2>
            <distortionK3>0.0</distortionK3>
            <distortionT1>0.0</distortionT1>
            <distortionT2>0.0</distortionT2>
            <CxPrime>0.0</CxPrime>
            <Cx>0.0</Cx>
            <Cy>0.0</Cy>
            <focalLength>0.0</focalLength>
            <robotNamespace>/</robotNamespace>
          </plugin>
          <pose>0 0.25 -0.08 3.14 0 1.57</pose>
        </sensor>
        <enable_wind>0</enable_wind>
        <kinematic>0</kinematic>
      </link>
      <joint name='gripper_finger1_inner_knuckle_joint' type='revolute'>
        <pose relative_to='wrist_3_link'>-0.0127 0.14142 0 3.14159 -0 1.5708</pose>
        <parent>wrist_3_link</parent>
        <child>gripper_finger1_inner_knuckle_link</child>
        <axis>
          <xyz>0 0 1</xyz>
          <limit>
            <effort>0.1</effort>
            <velocity>100</velocity>
            <lower>-1e+16</lower>
            <upper>1e+16</upper>
          </limit>
          <dynamics>
            <spring_reference>0</spring_reference>
            <spring_stiffness>0</spring_stiffness>
          </dynamics>
        </axis>
      </joint>
      <link name='gripper_finger1_inner_knuckle_link'>
        <pose relative_to='gripper_finger1_inner_knuckle_joint'>0 0 0 0 -0 0</pose>
        <inertial>
          <pose>0 0 0 0 -0 0</pose>
          <mass>0.029951</mass>
          <inertia>
            <ixx>3.9e-05</ixx>
            <ixy>0</ixy>
            <ixz>0</ixz>
            <iyy>5e-06</iyy>
            <iyz>0</iyz>
            <izz>3.5e-05</izz>
          </inertia>
        </inertial>
        <collision name='gripper_finger1_inner_knuckle_link_collision'>
          <pose>0.025 -0.02 0 0 0 -0.698</pose>
          <geometry>
            <box>
              <size>0.055 0.006 0.02</size>
            </box>
          </geometry>
          <surface>
            <contact>
              <ode>
                <kp>1e+08</kp>
                <kd>1</kd>
              </ode>
            </contact>
            <friction>
              <ode>
                <mu>100000</mu>
                <mu2>100000</mu2>
              </ode>
              <torsional>
                <ode/>
              </torsional>
            </friction>
            <bounce/>
          </surface>
          <max_contacts>10</max_contacts>
        </collision>
        <visual name='gripper_finger1_inner_knuckle_link_visual'>
          <pose>0 0 0 0 -0 0</pose>
          <geometry>
            <mesh>
              <scale>1 1 1</scale>
              <uri>/home/vedh/catkin_ws/src/robotiq_85_gripper-master/robotiq_85_description/meshes/visual/robotiq_85_inner_knuckle_link.dae</uri>
            </mesh>
          </geometry>
        </visual>
        <self_collide>0</self_collide>
        <enable_wind>0</enable_wind>
        <kinematic>0</kinematic>
      </link>
      <joint name='gripper_finger1_finger_tip_joint' type='revolute'>
        <pose relative_to='gripper_finger1_inner_knuckle_link'>0.04304 -0.037599 0 0 -0 0</pose>
        <parent>gripper_finger1_inner_knuckle_link</parent>
        <child>gripper_finger1_finger_tip_link</child>
        <axis>
          <xyz>0 0 1</xyz>
          <limit>
            <effort>100</effort>
            <velocity>100</velocity>
            <lower>-1e+16</lower>
            <upper>1e+16</upper>
          </limit>
          <dynamics>
            <spring_reference>0</spring_reference>
            <spring_stiffness>0</spring_stiffness>
          </dynamics>
        </axis>
      </joint>
      <link name='gripper_finger1_finger_tip_link'>
        <pose relative_to='gripper_finger1_finger_tip_joint'>0 0 0 0 -0 0</pose>
        <inertial>
          <pose>0 0 0 0 -0 0</pose>
          <mass>0.019555</mass>
          <inertia>
            <ixx>2e-06</ixx>
            <ixy>0</ixy>
            <ixz>0</ixz>
            <iyy>5e-06</iyy>
            <iyz>0</iyz>
            <izz>6e-06</izz>
          </inertia>
        </inertial>
        <collision name='gripper_finger1_finger_tip_link_collision'>
          <pose>0.02 0 0 0 -0 0</pose>
          <geometry>
            <box>
              <size>0.045 0.01 0.02</size>
            </box>
          </geometry>
          <surface>
            <contact>
              <ode>
                <kp>1e+08</kp>
                <kd>1</kd>
              </ode>
            </contact>
            <friction>
              <ode>
                <mu>100000</mu>
                <mu2>100000</mu2>
              </ode>
              <torsional>
                <ode/>
              </torsional>
            </friction>
            <bounce/>
          </surface>
          <max_contacts>10</max_contacts>
        </collision>
        <visual name='gripper_finger1_finger_tip_link_visual'>
          <pose>0 0 0 0 -0 0</pose>
          <geometry>
            <mesh>
              <scale>1 1 1</scale>
              <uri>/home/vedh/catkin_ws/src/robotiq_85_gripper-master/robotiq_85_description/meshes/visual/robotiq_85_finger_tip_link.dae</uri>
            </mesh>
          </geometry>
        </visual>
        <self_collide>0</self_collide>
        <enable_wind>0</enable_wind>
        <kinematic>0</kinematic>
      </link>
      <joint name='gripper_finger1_joint' type='revolute'>
        <pose relative_to='wrist_3_link'>-0.030601 0.134905 0 3.14159 -0 1.5708</pose>
        <parent>wrist_3_link</parent>
        <child>gripper_finger1_knuckle_link</child>
        <axis>
          <xyz>0 0 1</xyz>
          <limit>
            <lower>0</lower>
            <upper>0.804</upper>
            <effort>1000</effort>
            <velocity>2</velocity>
          </limit>
          <dynamics>
            <spring_reference>0</spring_reference>
            <spring_stiffness>0</spring_stiffness>
          </dynamics>
        </axis>
      </joint>
      <link name='gripper_finger1_knuckle_link'>
        <pose relative_to='gripper_finger1_joint'>0 0 0 0 -0 0</pose>
        <inertial>
          <pose>-0.002436 -0.018774 0 0 -0 0</pose>
          <mass>0.0458</mass>
          <inertia>
            <ixx>2.29304e-05</ixx>
            <ixy>-4.4183e-06</ixy>
            <ixz>0</ixz>
            <iyy>2.2184e-05</iyy>
            <iyz>0</iyz>
            <izz>4.11145e-05</izz>
          </inertia>
        </inertial>
        <collision name='gripper_finger1_knuckle_link_collision'>
          <pose>0 -0.01 0 0 0 -0.0873</pose>
          <geometry>
            <box>
              <size>0.012 0.035 0.014</size>
            </box>
          </geometry>
          <surface>
            <contact>
              <ode>
                <kp>1e+08</kp>
                <kd>1</kd>
              </ode>
            </contact>
            <friction>
              <ode>
                <mu>100000</mu>
                <mu2>100000</mu2>
              </ode>
              <torsional>
                <ode/>
              </torsional>
            </friction>
            <bounce/>
          </surface>
          <max_contacts>10</max_contacts>
        </collision>
        <collision name='gripper_finger1_knuckle_link_fixed_joint_lump__gripper_finger1_finger_link_collision_1'>
          <pose>0.020914 -0.033486 0 0 0 -0.175</pose>
          <geometry>
            <box>
              <size>0.0591 0.01 0.02</size>
            </box>
          </geometry>
          <surface>
            <contact>
              <ode>
                <kp>1e+08</kp>
                <kd>1</kd>
              </ode>
            </contact>
            <friction>
              <ode>
                <mu>100000</mu>
                <mu2>100000</mu2>
              </ode>
              <torsional>
                <ode/>
              </torsional>
            </friction>
            <bounce/>
          </surface>
          <max_contacts>10</max_contacts>
        </collision>
        <visual name='gripper_finger1_knuckle_link_visual'>
          <pose>0 0 0 0 -0 0</pose>
          <geometry>
            <mesh>
              <scale>1 1 1</scale>
              <uri>/home/vedh/catkin_ws/src/robotiq_85_gripper-master/robotiq_85_description/meshes/visual/robotiq_85_knuckle_link.dae</uri>
            </mesh>
          </geometry>
        </visual>
        <visual name='gripper_finger1_knuckle_link_fixed_joint_lump__gripper_finger1_finger_link_visual_1'>
          <pose>-0.004086 -0.031486 0 0 -0 0</pose>
          <geometry>
            <mesh>
              <scale>1 1 1</scale>
              <uri>/home/vedh/catkin_ws/src/robotiq_85_gripper-master/robotiq_85_description/meshes/visual/robotiq_85_finger_link.dae</uri>
            </mesh>
          </geometry>
        </visual>
        <self_collide>0</self_collide>
        <enable_wind>0</enable_wind>
        <kinematic>0</kinematic>
      </link>
      <joint name='gripper_finger2_inner_knuckle_joint' type='revolute'>
        <pose relative_to='wrist_3_link'>0.0127 0.14142 0 0 -0 1.5708</pose>
        <parent>wrist_3_link</parent>
        <child>gripper_finger2_inner_knuckle_link</child>
        <axis>
          <xyz>0 0 1</xyz>
          <limit>
            <effort>0.1</effort>
            <velocity>100</velocity>
            <lower>-1e+16</lower>
            <upper>1e+16</upper>
          </limit>
          <dynamics>
            <spring_reference>0</spring_reference>
            <spring_stiffness>0</spring_stiffness>
          </dynamics>
        </axis>
      </joint>
      <link name='gripper_finger2_inner_knuckle_link'>
        <pose relative_to='gripper_finger2_inner_knuckle_joint'>0 0 0 0 -0 0</pose>
        <inertial>
          <pose>0 0 0 0 -0 0</pose>
          <mass>0.029951</mass>
          <inertia>
            <ixx>3.9e-05</ixx>
            <ixy>0</ixy>
            <ixz>0</ixz>
            <iyy>5e-06</iyy>
            <iyz>0</iyz>
            <izz>3.5e-05</izz>
          </inertia>
        </inertial>
        <collision name='gripper_finger2_inner_knuckle_link_collision'>
          <pose>0.025 -0.02 0 0 0 -0.698</pose>
          <geometry>
            <box>
              <size>0.055 0.006 0.02</size>
            </box>
          </geometry>
          <surface>
            <contact>
              <ode>
                <kp>1e+08</kp>
                <kd>1</kd>
              </ode>
            </contact>
            <friction>
              <ode>
                <mu>100000</mu>
                <mu2>100000</mu2>
              </ode>
              <torsional>
                <ode/>
              </torsional>
            </friction>
            <bounce/>
          </surface>
          <max_contacts>10</max_contacts>
        </collision>
        <visual name='gripper_finger2_inner_knuckle_link_visual'>
          <pose>0 0 0 0 -0 0</pose>
          <geometry>
            <mesh>
              <scale>1 1 1</scale>
              <uri>/home/vedh/catkin_ws/src/robotiq_85_gripper-master/robotiq_85_description/meshes/visual/robotiq_85_inner_knuckle_link.dae</uri>
            </mesh>
          </geometry>
        </visual>
        <self_collide>0</self_collide>
        <enable_wind>0</enable_wind>
        <kinematic>0</kinematic>
      </link>
      <joint name='gripper_finger2_finger_tip_joint' type='revolute'>
        <pose relative_to='gripper_finger2_inner_knuckle_link'>0.04304 -0.037599 0 0 -0 0</pose>
        <parent>gripper_finger2_inner_knuckle_link</parent>
        <child>gripper_finger2_finger_tip_link</child>
        <axis>
          <xyz>0 0 1</xyz>
          <limit>
            <effort>100</effort>
            <velocity>100</velocity>
            <lower>-1e+16</lower>
            <upper>1e+16</upper>
          </limit>
          <dynamics>
            <spring_reference>0</spring_reference>
            <spring_stiffness>0</spring_stiffness>
          </dynamics>
        </axis>
      </joint>
      <link name='gripper_finger2_finger_tip_link'>
        <pose relative_to='gripper_finger2_finger_tip_joint'>0 0 0 0 -0 0</pose>
        <inertial>
          <pose>0 0 0 0 -0 0</pose>
          <mass>0.019555</mass>
          <inertia>
            <ixx>2e-06</ixx>
            <ixy>0</ixy>
            <ixz>0</ixz>
            <iyy>5e-06</iyy>
            <iyz>0</iyz>
            <izz>6e-06</izz>
          </inertia>
        </inertial>
        <collision name='gripper_finger2_finger_tip_link_collision'>
          <pose>0.02 0 0 0 -0 0</pose>
          <geometry>
            <box>
              <size>0.045 0.01 0.02</size>
            </box>
          </geometry>
          <surface>
            <contact>
              <ode>
                <kp>1e+08</kp>
                <kd>1</kd>
              </ode>
            </contact>
            <friction>
              <ode>
                <mu>100000</mu>
                <mu2>100000</mu2>
              </ode>
              <torsional>
                <ode/>
              </torsional>
            </friction>
            <bounce/>
          </surface>
          <max_contacts>10</max_contacts>
        </collision>
        <visual name='gripper_finger2_finger_tip_link_visual'>
          <pose>0 0 0 0 -0 0</pose>
          <geometry>
            <mesh>
              <scale>1 1 1</scale>
              <uri>/home/vedh/catkin_ws/src/robotiq_85_gripper-master/robotiq_85_description/meshes/visual/robotiq_85_finger_tip_link.dae</uri>
            </mesh>
          </geometry>
        </visual>
        <self_collide>0</self_collide>
        <enable_wind>0</enable_wind>
        <kinematic>0</kinematic>
      </link>
      <joint name='gripper_finger2_joint' type='revolute'>
        <pose relative_to='wrist_3_link'>0.030601 0.134905 0 0 -0 1.5708</pose>
        <parent>wrist_3_link</parent>
        <child>gripper_finger2_knuckle_link</child>
        <axis>
          <xyz>0 0 1</xyz>
          <limit>
            <lower>-3.14</lower>
            <upper>3.14</upper>
            <effort>1000</effort>
            <velocity>100</velocity>
          </limit>
          <dynamics>
            <spring_reference>0</spring_reference>
            <spring_stiffness>0</spring_stiffness>
          </dynamics>
        </axis>
      </joint>
      <link name='gripper_finger2_knuckle_link'>
        <pose relative_to='gripper_finger2_joint'>0 0 0 0 -0 0</pose>
        <inertial>
          <pose>-0.002436 -0.018774 0 0 -0 0</pose>
          <mass>0.0458</mass>
          <inertia>
            <ixx>2.29304e-05</ixx>
            <ixy>-4.4183e-06</ixy>
            <ixz>0</ixz>
            <iyy>2.2184e-05</iyy>
            <iyz>0</iyz>
            <izz>4.11145e-05</izz>
          </inertia>
        </inertial>
        <collision name='gripper_finger2_knuckle_link_collision'>
          <pose>0 -0.01 0 0 0 -0.0873</pose>
          <geometry>
            <box>
              <size>0.012 0.035 0.014</size>
            </box>
          </geometry>
          <surface>
            <contact>
              <ode>
                <kp>1e+08</kp>
                <kd>1</kd>
              </ode>
            </contact>
            <friction>
              <ode>
                <mu>100000</mu>
                <mu2>100000</mu2>
              </ode>
              <torsional>
                <ode/>
              </torsional>
            </friction>
            <bounce/>
          </surface>
          <max_contacts>10</max_contacts>
        </collision>
        <collision name='gripper_finger2_knuckle_link_fixed_joint_lump__gripper_finger2_finger_link_collision_1'>
          <pose>0.020914 -0.033486 0 0 0 -0.175</pose>
          <geometry>
            <box>
              <size>0.0591 0.01 0.02</size>
            </box>
          </geometry>
          <surface>
            <contact>
              <ode>
                <kp>1e+08</kp>
                <kd>1</kd>
              </ode>
            </contact>
            <friction>
              <ode>
                <mu>100000</mu>
                <mu2>100000</mu2>
              </ode>
              <torsional>
                <ode/>
              </torsional>
            </friction>
            <bounce/>
          </surface>
          <max_contacts>10</max_contacts>
        </collision>
        <visual name='gripper_finger2_knuckle_link_visual'>
          <pose>0 0 0 0 -0 0</pose>
          <geometry>
            <mesh>
              <scale>1 1 1</scale>
              <uri>/home/vedh/catkin_ws/src/robotiq_85_gripper-master/robotiq_85_description/meshes/visual/robotiq_85_knuckle_link.dae</uri>
            </mesh>
          </geometry>
        </visual>
        <visual name='gripper_finger2_knuckle_link_fixed_joint_lump__gripper_finger2_finger_link_visual_1'>
          <pose>-0.004086 -0.031486 0 0 -0 0</pose>
          <geometry>
            <mesh>
              <scale>1 1 1</scale>
              <uri>/home/vedh/catkin_ws/src/robotiq_85_gripper-master/robotiq_85_description/meshes/visual/robotiq_85_finger_link.dae</uri>
            </mesh>
          </geometry>
        </visual>
        <self_collide>0</self_collide>
        <enable_wind>0</enable_wind>
        <kinematic>0</kinematic>
      </link>
      <plugin name='control' filename='libgazebo_ros_control.so'>
        <robotNamespace>/</robotNamespace>
      </plugin>
      <plugin name='object_controller' filename='libgazebo_ros_planar_move.so'>
        <robotNamespace>/</robotNamespace>
      </plugin>
      <plugin name='right_force' filename='libcustom_force.so'>
        <bodyName>right_wheel_1</bodyName>
        <topicName>right_wheel_force</topicName>
        <robotNamespace>/</robotNamespace>
      </plugin>
      <plugin name='left_force' filename='libcustom_force.so'>
        <bodyName>left_wheel_1</bodyName>
        <topicName>left_wheel_force</topicName>
        <robotNamespace>/</robotNamespace>
      </plugin>
      <plugin name='front_force' filename='libcustom_force.so'>
        <bodyName>front_wheel_1</bodyName>
        <topicName>front_wheel_force</topicName>
        <robotNamespace>/</robotNamespace>
      </plugin>
      <static>0</static>
      <plugin name='mimic_robotiq_85_1' filename='libroboticsgroup_gazebo_mimic_joint_plugin.so'>
        <joint>gripper_finger1_joint</joint>
        <mimicJoint>gripper_finger2_joint</mimicJoint>
        <robotNamespace>/</robotNamespace>
      </plugin>
      <plugin name='mimic_robotiq_85_2' filename='libroboticsgroup_gazebo_mimic_joint_plugin.so'>
        <joint>gripper_finger1_joint</joint>
        <mimicJoint>gripper_finger2_inner_knuckle_joint</mimicJoint>
        <robotNamespace>/</robotNamespace>
      </plugin>
      <plugin name='mimic_robotiq_85_3' filename='libroboticsgroup_gazebo_mimic_joint_plugin.so'>
        <joint>gripper_finger1_joint</joint>
        <mimicJoint>gripper_finger1_inner_knuckle_joint</mimicJoint>
        <robotNamespace>/</robotNamespace>
      </plugin>
      <plugin name='mimic_robotiq_85_4' filename='libroboticsgroup_gazebo_mimic_joint_plugin.so'>
        <joint>gripper_finger1_joint</joint>
        <mimicJoint>gripper_finger1_finger_tip_joint</mimicJoint>
        <multiplier>-1.0</multiplier>
        <offset>0.0</offset>
        <robotNamespace>/</robotNamespace>
      </plugin>
      <plugin name='mimic_robotiq_85_5' filename='libroboticsgroup_gazebo_mimic_joint_plugin.so'>
        <joint>gripper_finger1_joint</joint>
        <mimicJoint>gripper_finger2_finger_tip_joint</mimicJoint>
        <multiplier>-1.0</multiplier>
        <offset>0.0</offset>
        <robotNamespace>/</robotNamespace>
      </plugin>
      <pose>0 0 0 0 -0 0</pose>
    </model>
    <model name='MalePatientBed'>
      <link name='link'>
        <pose>0 0 0 0 -0 0</pose>
        <visual name='visual'>
          <geometry>
            <mesh>
              <uri>model://MalePatientBed/meshes/MalePatientBed.obj</uri>
            </mesh>
          </geometry>
        </visual>
        <collision name='collision'>
          <geometry>
            <mesh>
              <uri>model://MalePatientBed/meshes/MalePatientBed.obj</uri>
            </mesh>
          </geometry>
          <max_contacts>10</max_contacts>
          <surface>
            <contact>
              <ode/>
            </contact>
            <bounce/>
            <friction>
              <torsional>
                <ode/>
              </torsional>
              <ode/>
            </friction>
          </surface>
        </collision>
        <self_collide>0</self_collide>
        <inertial>
          <pose>0 0 0 0 -0 0</pose>
          <inertia>
            <ixx>1</ixx>
            <ixy>0</ixy>
            <ixz>0</ixz>
            <iyy>1</iyy>
            <iyz>0</iyz>
            <izz>1</izz>
          </inertia>
          <mass>1</mass>
        </inertial>
        <enable_wind>0</enable_wind>
        <kinematic>0</kinematic>
      </link>
      <pose>-0.038119 -2.0285 0 0 -0 0</pose>
    </model>
    <model name='Hospital_room'>
      <pose>0.3882 -0.1588 0 0 -0 0</pose>
      <link name='Door_0'>
        <collision name='Door_0_Collision'>
          <geometry>
            <box>
              <size>0.9 0.17 2</size>
            </box>
          </geometry>
          <pose>0 0 1 0 -0 0</pose>
          <max_contacts>10</max_contacts>
          <surface>
            <contact>
              <ode/>
            </contact>
            <bounce/>
            <friction>
              <torsional>
                <ode/>
              </torsional>
              <ode/>
            </friction>
          </surface>
        </collision>
        <visual name='Door_0_Visual'>
          <pose>0 0 1 0 -0 0</pose>
          <geometry>
            <box>
              <size>0.9 0.17 2</size>
            </box>
          </geometry>
          <material>
            <script>
              <uri>file://media/materials/scripts/gazebo.material</uri>
              <name>Gazebo/Grey</name>
            </script>
          </material>
        </visual>
        <pose>-2.66668 -1.13911 0 0 -0 0</pose>
        <self_collide>0</self_collide>
        <enable_wind>0</enable_wind>
        <kinematic>0</kinematic>
      </link>
      <link name='Wall_10'>
        <collision name='Wall_10_Collision'>
          <geometry>
            <box>
              <size>6.5 0.15 2.5</size>
            </box>
          </geometry>
          <pose>0 0 1.25 0 -0 0</pose>
          <max_contacts>10</max_contacts>
          <surface>
            <contact>
              <ode/>
            </contact>
            <bounce/>
            <friction>
              <torsional>
                <ode/>
              </torsional>
              <ode/>
            </friction>
          </surface>
        </collision>
        <visual name='Wall_10_Visual'>
          <pose>0 0 1.25 0 -0 0</pose>
          <geometry>
            <box>
              <size>6.5 0.15 2.5</size>
            </box>
          </geometry>
          <material>
            <script>
              <uri>file://media/materials/scripts/gazebo.material</uri>
              <name>Gazebo/Wood</name>
            </script>
            <ambient>1 1 1 1</ambient>
          </material>
          <meta>
            <layer>0</layer>
          </meta>
        </visual>
        <pose>0.05 4.05 0 0 -0 3.14159</pose>
        <self_collide>0</self_collide>
        <enable_wind>0</enable_wind>
        <kinematic>0</kinematic>
      </link>
      <link name='Wall_11'>
        <collision name='Wall_11_Collision'>
          <geometry>
            <box>
              <size>5.25 0.15 2.5</size>
            </box>
          </geometry>
          <pose>0 0 1.25 0 -0 0</pose>
          <max_contacts>10</max_contacts>
          <surface>
            <contact>
              <ode/>
            </contact>
            <bounce/>
            <friction>
              <torsional>
                <ode/>
              </torsional>
              <ode/>
            </friction>
          </surface>
        </collision>
        <visual name='Wall_11_Visual'>
          <pose>0 0 1.25 0 -0 0</pose>
          <geometry>
            <box>
              <size>5.25 0.15 2.5</size>
            </box>
          </geometry>
          <material>
            <script>
              <uri>file://media/materials/scripts/gazebo.material</uri>
              <name>Gazebo/Wood</name>
            </script>
            <ambient>1 1 1 1</ambient>
          </material>
          <meta>
            <layer>0</layer>
          </meta>
        </visual>
        <pose>-3.125 1.5 0 0 -0 -1.5708</pose>
        <self_collide>0</self_collide>
        <enable_wind>0</enable_wind>
        <kinematic>0</kinematic>
      </link>
      <link name='Wall_13'>
        <collision name='Wall_13_Collision'>
          <geometry>
            <box>
              <size>2 0.15 2.5</size>
            </box>
          </geometry>
          <pose>0 0 1.25 0 -0 0</pose>
          <max_contacts>10</max_contacts>
          <surface>
            <contact>
              <ode/>
            </contact>
            <bounce/>
            <friction>
              <torsional>
                <ode/>
              </torsional>
              <ode/>
            </friction>
          </surface>
        </collision>
        <visual name='Wall_13_Visual'>
          <pose>0 0 1.25 0 -0 0</pose>
          <geometry>
            <box>
              <size>2 0.15 2.5</size>
            </box>
          </geometry>
          <material>
            <script>
              <uri>file://media/materials/scripts/gazebo.material</uri>
              <name>Gazebo/Wood</name>
            </script>
            <ambient>1 1 1 1</ambient>
          </material>
          <meta>
            <layer>0</layer>
          </meta>
        </visual>
        <pose>-3.225 -3.125 0 0 -0 1.5708</pose>
        <self_collide>0</self_collide>
        <enable_wind>0</enable_wind>
        <kinematic>0</kinematic>
      </link>
      <link name='Wall_6'>
        <collision name='Wall_6_Collision'>
          <geometry>
            <box>
              <size>3.25 0.15 2.5</size>
            </box>
          </geometry>
          <pose>0 0 1.25 0 -0 0</pose>
          <max_contacts>10</max_contacts>
          <surface>
            <contact>
              <ode/>
            </contact>
            <bounce/>
            <friction>
              <torsional>
                <ode/>
              </torsional>
              <ode/>
            </friction>
          </surface>
        </collision>
        <visual name='Wall_6_Visual'>
          <pose>0 0 1.25 0 -0 0</pose>
          <geometry>
            <box>
              <size>3.25 0.15 2.5</size>
            </box>
          </geometry>
          <material>
            <script>
              <uri>file://media/materials/scripts/gazebo.material</uri>
              <name>Gazebo/Wood</name>
            </script>
            <ambient>1 1 1 1</ambient>
          </material>
          <meta>
            <layer>0</layer>
          </meta>
        </visual>
        <pose>-1.675 -4.05 0 0 -0 3.14159</pose>
        <self_collide>0</self_collide>
        <enable_wind>0</enable_wind>
        <kinematic>0</kinematic>
      </link>
      <link name='Wall_8'>
        <pose>1.55 -4.05 0 0 -0 0</pose>
        <visual name='Wall_8_Visual_0'>
          <pose>-1.31734 0 1.25 0 -0 0</pose>
          <geometry>
            <box>
              <size>0.865327 0.15 2.5</size>
            </box>
          </geometry>
          <material>
            <script>
              <uri>file://media/materials/scripts/gazebo.material</uri>
              <name>Gazebo/Wood</name>
            </script>
            <ambient>1 1 1 1</ambient>
          </material>
          <meta>
            <layer>0</layer>
          </meta>
        </visual>
        <collision name='Wall_8_Collision_0'>
          <geometry>
            <box>
              <size>0.865327 0.15 2.5</size>
            </box>
          </geometry>
          <pose>-1.31734 0 1.25 0 -0 0</pose>
          <max_contacts>10</max_contacts>
          <surface>
            <contact>
              <ode/>
            </contact>
            <bounce/>
            <friction>
              <torsional>
                <ode/>
              </torsional>
              <ode/>
            </friction>
          </surface>
        </collision>
        <visual name='Wall_8_Visual_1'>
          <pose>0.432664 0 0.25 0 -0 0</pose>
          <geometry>
            <box>
              <size>2.63467 0.15 0.5</size>
            </box>
          </geometry>
          <material>
            <script>
              <uri>file://media/materials/scripts/gazebo.material</uri>
              <name>Gazebo/Wood</name>
            </script>
            <ambient>1 1 1 1</ambient>
          </material>
          <meta>
            <layer>0</layer>
          </meta>
        </visual>
        <collision name='Wall_8_Collision_1'>
          <geometry>
            <box>
              <size>2.63467 0.15 0.5</size>
            </box>
          </geometry>
          <pose>0.432664 0 0.25 0 -0 0</pose>
          <max_contacts>10</max_contacts>
          <surface>
            <contact>
              <ode/>
            </contact>
            <bounce/>
            <friction>
              <torsional>
                <ode/>
              </torsional>
              <ode/>
            </friction>
          </surface>
        </collision>
        <visual name='Wall_8_Visual_2'>
          <pose>0.832664 0 1.5 0 -0 0</pose>
          <geometry>
            <box>
              <size>1.83467 0.15 2</size>
            </box>
          </geometry>
          <material>
            <script>
              <uri>file://media/materials/scripts/gazebo.material</uri>
              <name>Gazebo/Wood</name>
            </script>
            <ambient>1 1 1 1</ambient>
          </material>
          <meta>
            <layer>0</layer>
          </meta>
        </visual>
        <collision name='Wall_8_Collision_2'>
          <geometry>
            <box>
              <size>1.83467 0.15 2</size>
            </box>
          </geometry>
          <pose>0.832664 0 1.5 0 -0 0</pose>
          <max_contacts>10</max_contacts>
          <surface>
            <contact>
              <ode/>
            </contact>
            <bounce/>
            <friction>
              <torsional>
                <ode/>
              </torsional>
              <ode/>
            </friction>
          </surface>
        </collision>
        <visual name='Wall_8_Visual_3'>
          <pose>-0.484673 0 1.9 0 -0 0</pose>
          <geometry>
            <box>
              <size>0.8 0.15 1.2</size>
            </box>
          </geometry>
          <material>
            <script>
              <uri>file://media/materials/scripts/gazebo.material</uri>
              <name>Gazebo/Wood</name>
            </script>
            <ambient>1 1 1 1</ambient>
          </material>
          <meta>
            <layer>0</layer>
          </meta>
        </visual>
        <collision name='Wall_8_Collision_3'>
          <geometry>
            <box>
              <size>0.8 0.15 1.2</size>
            </box>
          </geometry>
          <pose>-0.484673 0 1.9 0 -0 0</pose>
          <max_contacts>10</max_contacts>
          <surface>
            <contact>
              <ode/>
            </contact>
            <bounce/>
            <friction>
              <torsional>
                <ode/>
              </torsional>
              <ode/>
            </friction>
          </surface>
        </collision>
        <self_collide>0</self_collide>
        <enable_wind>0</enable_wind>
        <kinematic>0</kinematic>
      </link>
      <link name='Wall_9'>
        <collision name='Wall_9_Collision'>
          <geometry>
            <box>
              <size>8.25 0.15 2.5</size>
            </box>
          </geometry>
          <pose>0 0 1.25 0 -0 0</pose>
          <max_contacts>10</max_contacts>
          <surface>
            <contact>
              <ode/>
            </contact>
            <bounce/>
            <friction>
              <torsional>
                <ode/>
              </torsional>
              <ode/>
            </friction>
          </surface>
        </collision>
        <visual name='Wall_9_Visual'>
          <pose>0 0 1.25 0 -0 0</pose>
          <geometry>
            <box>
              <size>8.25 0.15 2.5</size>
            </box>
          </geometry>
          <material>
            <script>
              <uri>file://media/materials/scripts/gazebo.material</uri>
              <name>Gazebo/Wood</name>
            </script>
            <ambient>1 1 1 1</ambient>
          </material>
          <meta>
            <layer>0</layer>
          </meta>
        </visual>
        <pose>3.225 0 0 0 -0 1.5708</pose>
        <self_collide>0</self_collide>
        <enable_wind>0</enable_wind>
        <kinematic>0</kinematic>
      </link>
      <static>1</static>
    </model>
    <model name='AdjTable'>
      <static>1</static>
      <link name='body'>
        <pose>0 0 0 0 -0 0</pose>
        <visual name='visual'>
          <geometry>
            <mesh>
              <uri>model://AdjTable/meshes/AdjTable.obj</uri>
            </mesh>
          </geometry>
        </visual>
        <collision name='collision'>
          <geometry>
            <mesh>
              <uri>model://AdjTable/meshes/AdjTable_Col.obj</uri>
            </mesh>
          </geometry>
          <max_contacts>10</max_contacts>
          <surface>
            <contact>
              <ode/>
            </contact>
            <bounce/>
            <friction>
              <torsional>
                <ode/>
              </torsional>
              <ode/>
            </friction>
          </surface>
        </collision>
        <self_collide>0</self_collide>
        <enable_wind>0</enable_wind>
        <kinematic>0</kinematic>
      </link>
      <pose>2.37579 0.903049 0 0 -0 0</pose>
    </model>
    <model name='Chair'>
      <link name='body'>
        <pose>0 0 0 0 -0 1.5708</pose>
        <visual name='visual'>
          <geometry>
            <mesh>
              <uri>model://Chair/meshes/Chair.obj</uri>
              <scale>0.00817 0.00817 0.00817</scale>
            </mesh>
          </geometry>
        </visual>
        <collision name='collision'>
          <geometry>
            <mesh>
              <uri>model://Chair/meshes/Chair.obj</uri>
              <scale>0.00817 0.00817 0.00817</scale>
            </mesh>
          </geometry>
          <max_contacts>10</max_contacts>
          <surface>
            <contact>
              <ode/>
            </contact>
            <bounce/>
            <friction>
              <torsional>
                <ode/>
              </torsional>
              <ode/>
            </friction>
          </surface>
        </collision>
        <self_collide>0</self_collide>
        <inertial>
          <pose>0 0 0 0 -0 0</pose>
          <inertia>
            <ixx>1</ixx>
            <ixy>0</ixy>
            <ixz>0</ixz>
            <iyy>1</iyy>
            <iyz>0</iyz>
            <izz>1</izz>
          </inertia>
          <mass>1</mass>
        </inertial>
        <enable_wind>0</enable_wind>
        <kinematic>0</kinematic>
      </link>
      <pose>2.20366 0.821892 0 0 -0 0</pose>
    </model>
    <model name='MetalCabinet'>
      <static>1</static>
      <link name='body'>
        <pose>0 0 0 0 -0 0</pose>
        <visual name='visual'>
          <geometry>
            <mesh>
              <uri>model://MetalCabinet/meshes/MetalCabinet.obj</uri>
            </mesh>
          </geometry>
        </visual>
        <collision name='collision'>
          <geometry>
            <mesh>
              <uri>model://MetalCabinet/meshes/MetalCabinet.obj</uri>
            </mesh>
          </geometry>
          <max_contacts>10</max_contacts>
          <surface>
            <contact>
              <ode/>
            </contact>
            <bounce/>
            <friction>
              <torsional>
                <ode/>
              </torsional>
              <ode/>
            </friction>
          </surface>
        </collision>
        <self_collide>0</self_collide>
        <enable_wind>0</enable_wind>
        <kinematic>0</kinematic>
      </link>
      <pose>3.0627 3.52298 0 0 -0 0</pose>
    </model>
    <model name='MaleVisitorOnPhone'>
      <static>1</static>
      <link name='body'>
        <pose>0 0 0 0 -0 0</pose>
        <visual name='visual'>
          <geometry>
            <mesh>
              <uri>model://MaleVisitorOnPhone/meshes/MaleVisitorStatic.obj</uri>
            </mesh>
          </geometry>
        </visual>
        <collision name='collision'>
          <geometry>
            <mesh>
              <uri>model://MaleVisitorOnPhone/meshes/MaleVisitorStatic_Col.obj</uri>
            </mesh>
          </geometry>
          <max_contacts>10</max_contacts>
          <surface>
            <contact>
              <ode/>
            </contact>
            <bounce/>
            <friction>
              <torsional>
                <ode/>
              </torsional>
              <ode/>
            </friction>
          </surface>
        </collision>
        <self_collide>0</self_collide>
        <enable_wind>0</enable_wind>
        <kinematic>0</kinematic>
      </link>
      <pose>-2.16948 -1.95211 0 0 -0 0</pose>
    </model>
    <model name='SurgicalTrolley'>
      <static>1</static>
      <link name='body'>
        <pose>0 0 0 0 -0 0</pose>
        <visual name='visual'>
          <geometry>
            <mesh>
              <uri>model://SurgicalTrolley/meshes/trolley.obj</uri>
            </mesh>
          </geometry>
        </visual>
        <collision name='collision'>
          <geometry>
            <mesh>
              <uri>model://SurgicalTrolley/meshes/trolley.obj</uri>
            </mesh>
          </geometry>
          <max_contacts>10</max_contacts>
          <surface>
            <contact>
              <ode/>
            </contact>
            <bounce/>
            <friction>
              <torsional>
                <ode/>
              </torsional>
              <ode/>
            </friction>
          </surface>
        </collision>
        <self_collide>0</self_collide>
        <enable_wind>0</enable_wind>
        <kinematic>0</kinematic>
      </link>
      <pose>1.25584 0.675192 0 0 -0 0</pose>
    </model>
    <model name='MopCart3'>
      <link name='link'>
        <pose>0 0 0 0 -0 0</pose>
        <visual name='visual'>
          <geometry>
            <mesh>
              <uri>model://MopCart3/meshes/MopCart3.obj</uri>
            </mesh>
          </geometry>
        </visual>
        <collision name='collision'>
          <geometry>
            <mesh>
              <uri>model://MopCart3/meshes/MopCart3.obj</uri>
            </mesh>
          </geometry>
          <max_contacts>10</max_contacts>
          <surface>
            <contact>
              <ode/>
            </contact>
            <bounce/>
            <friction>
              <torsional>
                <ode/>
              </torsional>
              <ode/>
            </friction>
          </surface>
        </collision>
        <self_collide>0</self_collide>
        <inertial>
          <pose>0 0 0 0 -0 0</pose>
          <inertia>
            <ixx>1</ixx>
            <ixy>0</ixy>
            <ixz>0</ixz>
            <iyy>1</iyy>
            <iyz>0</iyz>
            <izz>1</izz>
          </inertia>
          <mass>1</mass>
        </inertial>
        <enable_wind>0</enable_wind>
        <kinematic>0</kinematic>
      </link>
      <pose>2.05923 3.50272 0 0 -0 0</pose>
    </model>
    <model name='InstrumentCart1'>
      <static>1</static>
      <link name='body'>
        <pose>0 0 0 0 -0 0</pose>
        <visual name='visual'>
          <geometry>
            <mesh>
              <uri>model://InstrumentCart1/meshes/InstrumentCart1.obj</uri>
            </mesh>
          </geometry>
        </visual>
        <collision name='collision'>
          <geometry>
            <mesh>
              <uri>model://InstrumentCart1/meshes/InstrumentCart1.obj</uri>
            </mesh>
          </geometry>
          <max_contacts>10</max_contacts>
          <surface>
            <contact>
              <ode/>
            </contact>
            <bounce/>
            <friction>
              <torsional>
                <ode/>
              </torsional>
              <ode/>
            </friction>
          </surface>
        </collision>
        <self_collide>0</self_collide>
        <enable_wind>0</enable_wind>
        <kinematic>0</kinematic>
      </link>
      <pose>-0.302839 3.31436 0 0 -0 0</pose>
    </model>
    <model name='IVStand'>
      <link name='body'>
        <pose>0 0 0 0 -0 0</pose>
        <visual name='visual'>
          <geometry>
            <mesh>
              <uri>model://IVStand/meshes/IVStand.obj</uri>
              <scale>0.00817 0.00817 0.00817</scale>
            </mesh>
          </geometry>
        </visual>
        <collision name='collision'>
          <geometry>
            <mesh>
              <uri>model://IVStand/meshes/IVStand.obj</uri>
              <scale>0.00817 0.00817 0.00817</scale>
            </mesh>
          </geometry>
          <max_contacts>10</max_contacts>
          <surface>
            <contact>
              <ode/>
            </contact>
            <bounce/>
            <friction>
              <torsional>
                <ode/>
              </torsional>
              <ode/>
            </friction>
          </surface>
        </collision>
        <self_collide>0</self_collide>
        <inertial>
          <pose>0 0 0 0 -0 0</pose>
          <inertia>
            <ixx>1</ixx>
            <ixy>0</ixy>
            <ixz>0</ixz>
            <iyy>1</iyy>
            <iyz>0</iyz>
            <izz>1</izz>
          </inertia>
          <mass>1</mass>
        </inertial>
        <enable_wind>0</enable_wind>
        <kinematic>0</kinematic>
      </link>
      <pose>-1.01294 3.29467 0 0 -0 0</pose>
    </model>
    <model name='CGMClassic'>
      <static>1</static>
      <link name='body'>
        <pose>0 0 0 0 -0 0</pose>
        <visual name='visual'>
          <geometry>
            <mesh>
              <uri>model://CGMClassic/meshes/CGMClassic.obj</uri>
              <scale>0.01 0.01 0.01</scale>
            </mesh>
          </geometry>
        </visual>
        <collision name='collision'>
          <geometry>
            <mesh>
              <uri>model://CGMClassic/meshes/CGMClassic.obj</uri>
              <scale>0.01 0.01 0.01</scale>
            </mesh>
          </geometry>
          <max_contacts>10</max_contacts>
          <surface>
            <contact>
              <ode/>
            </contact>
            <bounce/>
            <friction>
              <torsional>
                <ode/>
              </torsional>
              <ode/>
            </friction>
          </surface>
        </collision>
        <self_collide>0</self_collide>
        <enable_wind>0</enable_wind>
        <kinematic>0</kinematic>
      </link>
      <pose>-0.943809 2.21096 0 0 -0 0</pose>
    </model>
    <state world_name='default'>
      <sim_time>607 547000000</sim_time>
      <real_time>753 912844758</real_time>
      <wall_time>1676177588 288152270</wall_time>
      <iterations>607547</iterations>
      <model name='ADHIC_MK1'>
        <pose>0.230906 -0.737132 0.052736 0.002408 0.008647 -1.81442</pose>
        <scale>1 1 1</scale>
        <link name='base_footprint'>
          <pose>0.230906 -0.737132 0.052736 0.002408 0.008647 -1.81442</pose>
          <velocity>-0.002044 -0.001436 0.001605 -0.000923 0.004328 0.003076</velocity>
          <acceleration>-1.4735 -1.31689 1.60815 -2.33358 -1.12601 2.80164</acceleration>
          <wrench>-9.34569 -8.3524 10.1997 0 -0 0</wrench>
        </link>
        <link name='forearm_link'>
          <pose>0.316482 -0.453997 0.645005 0.26787 -1.56187 -2.08231</pose>
          <velocity>0.001165 0.000902 -0.002877 -0.007703 0.002764 0.002548</velocity>
          <acceleration>0.685118 1.03603 -4.47371 -0.233513 1.25274 3.07576</acceleration>
          <wrench>1.55864 2.35697 -10.1777 0 -0 0</wrench>
        </link>
        <link name='front_wheel_1'>
          <pose>0.210307 -0.81959 0.054505 0.875992 0.008631 -1.81421</pose>
          <velocity>-0.001568 -0.000909 0.002302 0.043049 0.09932 0.054509</velocity>
          <acceleration>-1.04745 -1.03639 2.12374 2.15514 -0.130804 0.693025</acceleration>
          <wrench>-0.370018 -0.366109 0.750223 0 -0 0</wrench>
        </link>
        <link name='gripper_finger1_finger_tip_link'>
          <pose>0.496616 0.09463 0.744691 3.13917 -0.008392 1.32723</pose>
          <velocity>-0.000454 0.002302 -0.018561 -0.090513 0.010252 -0.000319</velocity>
          <acceleration>-0.453779 2.30249 -18.5609 1.93315 -0.54662 -0.316361</acceleration>
          <wrench>-0.008874 0.045025 -0.362959 0 -0 0</wrench>
        </link>
        <link name='gripper_finger1_inner_knuckle_link'>
          <pose>0.522727 0.043794 0.744418 3.13917 -0.008385 1.32725</pose>
          <velocity>0.00045 0.002764 -0.015578 -0.093124 0.009942 0.018296</velocity>
          <acceleration>0.449993 2.76387 -15.578 -0.15864 -0.891151 -2.00586</acceleration>
          <wrench>0.013478 0.082781 -0.466576 0 -0 0</wrench>
        </link>
        <link name='gripper_finger1_knuckle_link'>
          <pose>0.503783 0.04179 0.74432 3.13925 -0.008569 1.32717</pose>
          <velocity>0.000486 0.002537 -0.01493 -0.01781 0.022554 0.0098</velocity>
          <acceleration>0.463475 2.35177 -14.5441 0.230148 1.05874 2.5438</acceleration>
          <wrench>0.021227 0.107711 -0.666119 0 -0 0</wrench>
        </link>
        <link name='gripper_finger2_finger_tip_link'>
          <pose>0.59425 0.07036 0.744931 -0.002361 -0.008394 1.32713</pose>
          <velocity>0.001315 0.001911 -0.019156 -0.101538 0.035533 -0.000169</velocity>
          <acceleration>1.31542 1.91113 -19.1561 2.87398 0.79739 -2.98475</acceleration>
          <wrench>0.025723 0.037372 -0.374598 0 -0 0</wrench>
        </link>
        <link name='gripper_finger2_inner_knuckle_link'>
          <pose>0.547377 0.037666 0.744478 -0.002362 -0.008387 1.32709</pose>
          <velocity>0.000515 0.003047 -0.015776 -0.104675 0.035935 -0.025063</velocity>
          <acceleration>0.514643 3.04654 -15.7761 -0.43198 -0.441427 1.61003</acceleration>
          <wrench>0.015414 0.091247 -0.472509 0 -0 0</wrench>
        </link>
        <link name='gripper_finger2_knuckle_link'>
          <pose>0.563178 0.027025 0.744465 -0.002358 -0.008574 1.3271</pose>
          <velocity>0.000667 0.003242 -0.015693 -0.017054 0.016027 -0.048333</velocity>
          <acceleration>0.334245 2.39009 -15.8576 1.85481 -0.196956 1.99197</acceleration>
          <wrench>0.015308 0.109466 -0.726279 0 -0 0</wrench>
        </link>
        <link name='left_wheel_1'>
          <pose>0.312569 -0.713672 0.05581 2.52552 -0.775365 2.63633</pose>
          <velocity>-0.001728 -0.000956 0.00121 -0.022368 -0.049272 0.030847</velocity>
          <acceleration>-1.81727 -0.657955 1.62204 -2.81009 -0.951766 2.67635</acceleration>
          <wrench>-0.641961 -0.232426 0.572994 0 -0 0</wrench>
        </link>
        <link name='right_wheel_1'>
          <pose>0.169786 -0.678042 0.055438 2.21119 0.949984 -0.223226</pose>
          <velocity>-0.002684 -0.00129 0.000976 0.040077 -0.057676 0.011507</velocity>
          <acceleration>-2.76573 -1.37336 0.839396 -1.69663 1.3029 2.13334</acceleration>
          <wrench>-0.977009 -0.485146 0.296521 0 -0 0</wrench>
        </link>
        <link name='shoulder_link'>
          <pose>0.229627 -0.739391 0.341882 0.002414 0.00867 -1.81442</pose>
          <velocity>-0.000766 -0.001334 0.00162 0.001488 0.004029 0.00753</velocity>
          <acceleration>-0.766429 -1.33393 1.61965 -2.26276 -1.46727 1.85879</acceleration>
          <wrench>-2.83579 -4.93555 5.99271 0 -0 0</wrench>
        </link>
        <link name='upper_arm_link'>
          <pose>0.361464 -0.77217 0.342197 0.003295 -0.776792 -1.81676</pose>
          <velocity>-0.000525 -0.001484 0.000988 -0.008626 0.006221 0.000411</velocity>
          <acceleration>0.63846 0.257574 -0.948069 -2.13252 1.19643 2.60404</acceleration>
          <wrench>5.3586 2.16182 -7.95714 0 -0 0</wrench>
        </link>
        <link name='wrist_1_link'>
          <pose>0.4111 -0.073343 0.648377 0.002352 0.008611 -1.81443</pose>
          <velocity>8.4e-05 0.000492 -0.009026 -0.008127 0.010614 0.004455</velocity>
          <acceleration>0.186412 0.895615 -9.80141 -0.16192 -0.309871 -1.85995</acceleration>
          <wrench>0.227237 1.09176 -11.9479 0 -0 0</wrench>
        </link>
        <link name='wrist_2_link'>
          <pose>0.501353 -0.095775 0.648595 0.008586 -0.002359 -0.243653</pose>
          <velocity>0.000671 0.001562 -0.010176 -0.011771 0.014263 0.009891</velocity>
          <acceleration>2.02782 2.67191 -10.161 -0.902697 0.077436 -2.66159</acceleration>
          <wrench>2.47192 3.25705 -12.3863 0 -0 0</wrench>
        </link>
        <link name='wrist_3_link'>
          <pose>0.500939 -0.096509 0.743237 0.008578 -0.002355 -0.243649</pose>
          <velocity>0.001969 0.002599 -0.012181 -0.015407 0.015813 0.010514</velocity>
          <acceleration>1.19792 2.80382 -13.618 3.02219 0.174698 -0.009985</acceleration>
          <wrench>0.988118 2.31276 -11.233 0 -0 0</wrench>
        </link>
      </model>
      <model name='AdjTable'>
        <pose>2.82505 0.890537 0 0 0 -1.59864</pose>
        <scale>1 1 1</scale>
        <link name='body'>
          <pose>2.82505 0.890537 0 0 0 -1.59864</pose>
          <velocity>0 0 0 0 -0 0</velocity>
          <acceleration>0 0 0 0 -0 0</acceleration>
          <wrench>0 0 0 0 -0 0</wrench>
        </link>
      </model>
      <model name='CGMClassic'>
        <pose>-0.943809 2.21096 0 0 -0 0</pose>
        <scale>1 1 1</scale>
        <link name='body'>
          <pose>-0.943809 2.21096 0 0 -0 0</pose>
          <velocity>0 0 0 0 -0 0</velocity>
          <acceleration>0 0 0 0 -0 0</acceleration>
          <wrench>0 0 0 0 -0 0</wrench>
        </link>
      </model>
      <model name='Chair'>
        <pose>2.20366 0.821892 2e-06 -1e-05 -3e-06 0</pose>
        <scale>1 1 1</scale>
        <link name='body'>
          <pose>2.20366 0.821892 2e-06 -3e-06 1e-05 1.5708</pose>
          <velocity>0 0 0 0 -0 0</velocity>
          <acceleration>-2.5e-05 -3.9e-05 16.689 -2.01259 1.56638 -3.14159</acceleration>
          <wrench>-2.5e-05 -3.9e-05 16.689 0 -0 0</wrench>
        </link>
      </model>
      <model name='Hospital_room'>
        <pose>0.3882 -0.1588 0 0 -0 0</pose>
        <scale>1 1 1</scale>
        <link name='Door_0'>
          <pose>-2.27848 -1.29791 0 0 -0 0</pose>
          <velocity>0 0 0 0 -0 0</velocity>
          <acceleration>0 0 0 0 -0 0</acceleration>
          <wrench>0 0 0 0 -0 0</wrench>
        </link>
        <link name='Wall_10'>
          <pose>0.4382 3.8912 0 0 -0 3.14159</pose>
          <velocity>0 0 0 0 -0 0</velocity>
          <acceleration>0 0 0 0 -0 0</acceleration>
          <wrench>0 0 0 0 -0 0</wrench>
        </link>
        <link name='Wall_11'>
          <pose>-2.7368 1.3412 0 0 0 -1.5708</pose>
          <velocity>0 0 0 0 -0 0</velocity>
          <acceleration>0 0 0 0 -0 0</acceleration>
          <wrench>0 0 0 0 -0 0</wrench>
        </link>
        <link name='Wall_13'>
          <pose>-2.8368 -3.2838 0 0 -0 1.5708</pose>
          <velocity>0 0 0 0 -0 0</velocity>
          <acceleration>0 0 0 0 -0 0</acceleration>
          <wrench>0 0 0 0 -0 0</wrench>
        </link>
        <link name='Wall_6'>
          <pose>-1.2868 -4.2088 0 0 -0 3.14159</pose>
          <velocity>0 0 0 0 -0 0</velocity>
          <acceleration>0 0 0 0 -0 0</acceleration>
          <wrench>0 0 0 0 -0 0</wrench>
        </link>
        <link name='Wall_8'>
          <pose>1.9382 -4.2088 0 0 -0 0</pose>
          <velocity>0 0 0 0 -0 0</velocity>
          <acceleration>0 0 0 0 -0 0</acceleration>
          <wrench>0 0 0 0 -0 0</wrench>
        </link>
        <link name='Wall_9'>
          <pose>3.6132 -0.1588 0 0 -0 1.5708</pose>
          <velocity>0 0 0 0 -0 0</velocity>
          <acceleration>0 0 0 0 -0 0</acceleration>
          <wrench>0 0 0 0 -0 0</wrench>
        </link>
      </model>
      <model name='IVStand'>
        <pose>-1.01294 3.29467 0.000669 -1.8e-05 -2e-06 0</pose>
        <scale>1 1 1</scale>
        <link name='body'>
          <pose>-1.01294 3.29467 0.000669 -1.8e-05 -2e-06 0</pose>
          <velocity>0 0 0 0 -0 0</velocity>
          <acceleration>0 0 -9.8 0 -0 0</acceleration>
          <wrench>0 0 -9.8 0 -0 0</wrench>
        </link>
      </model>
      <model name='InstrumentCart1'>
        <pose>-0.302839 3.31436 0 0 -0 0</pose>
        <scale>1 1 1</scale>
        <link name='body'>
          <pose>-0.302839 3.31436 0 0 -0 0</pose>
          <velocity>0 0 0 0 -0 0</velocity>
          <acceleration>0 0 0 0 -0 0</acceleration>
          <wrench>0 0 0 0 -0 0</wrench>
        </link>
      </model>
      <model name='MalePatientBed'>
        <pose>-0.038119 -2.0285 0.001659 0 -1e-06 0</pose>
        <scale>1 1 1</scale>
        <link name='link'>
          <pose>-0.038119 -2.0285 0.001659 0 -1e-06 0</pose>
          <velocity>0 0 0 0 -0 0</velocity>
          <acceleration>-0.01339 9e-06 -0.208699 -3.14158 -1.36474 3.14158</acceleration>
          <wrench>-0.01339 9e-06 -0.208699 0 -0 0</wrench>
        </link>
      </model>
      <model name='MaleVisitorOnPhone'>
        <pose>-2.16948 -1.95211 0 0 -0 0</pose>
        <scale>1 1 1</scale>
        <link name='body'>
          <pose>-2.16948 -1.95211 0 0 -0 0</pose>
          <velocity>0 0 0 0 -0 0</velocity>
          <acceleration>0 0 0 0 -0 0</acceleration>
          <wrench>0 0 0 0 -0 0</wrench>
        </link>
      </model>
      <model name='MetalCabinet'>
        <pose>3.0627 3.52298 0 0 -0 0</pose>
        <scale>1 1 1</scale>
        <link name='body'>
          <pose>3.0627 3.52298 0 0 -0 0</pose>
          <velocity>0 0 0 0 -0 0</velocity>
          <acceleration>0 0 0 0 -0 0</acceleration>
          <wrench>0 0 0 0 -0 0</wrench>
        </link>
      </model>
      <model name='MopCart3'>
        <pose>2.05923 3.50272 -5.8e-05 1e-06 -1e-06 0</pose>
        <scale>1 1 1</scale>
        <link name='link'>
          <pose>2.05923 3.50272 -5.8e-05 1e-06 -1e-06 0</pose>
          <velocity>0 0 0 0 -0 0</velocity>
          <acceleration>9.4e-05 0.000112 -0.652047 -1.21084 -1.5255 3.14159</acceleration>
          <wrench>9.4e-05 0.000112 -0.652047 0 -0 0</wrench>
        </link>
      </model>
      <model name='SurgicalTrolley'>
        <pose>1.25584 0.675192 0 0 -0 0</pose>
        <scale>1 1 1</scale>
        <link name='body'>
          <pose>1.25584 0.675192 0 0 -0 0</pose>
          <velocity>0 0 0 0 -0 0</velocity>
          <acceleration>0 0 0 0 -0 0</acceleration>
          <wrench>0 0 0 0 -0 0</wrench>
        </link>
      </model>
      <model name='ground_plane'>
        <pose>0 0 0 0 -0 0</pose>
        <scale>1 1 1</scale>
        <link name='link'>
          <pose>0 0 0 0 -0 0</pose>
          <velocity>0 0 0 0 -0 0</velocity>
          <acceleration>0 0 0 0 -0 0</acceleration>
          <wrench>0 0 0 0 -0 0</wrench>
        </link>
      </model>
      <light name='sun'>
        <pose>0 0 10 0 -0 0</pose>
      </light>
    </state>
    <gui fullscreen='0'>
      <camera name='user_camera'>
        <pose>1.27008 -4.94723 8.97542 0 0.85564 1.48019</pose>
        <view_controller>orbit</view_controller>
        <projection_type>perspective</projection_type>
      </camera>
    </gui>
  </world>
</sdf>
